---
title: エラー処理と例外処理
---

>オブジェクト指向プログラミングおよび演習1 第8回  
>  
> 予期しない出来事に対処できるプログラムを組めるようになろう！


プログラムを作成する上で、予期しない状況やエラーへの対応は避けて通れません。

今回はエラー処理、とくに例外処理の仕組みを理解し、堅牢なプログラムを作成するための知識と技術を習得します。

## 1. 予期しない動作に対応する

まずは、プログラム実行中に遭遇する可能性のある「エラー」について理解を深めましょう。

### 1.1. エラーの種類

エラーには主に以下の3つの種類があります。それぞれ、いつ気づくか、どう修正するかが異なります。

* 構文エラー (Syntax Error)
* 実行時エラー (Runtime Error)
* 論理エラー (Logic Error)

#### 1.1.1. 構文エラー (Syntax Error)

コードの文法的な誤りにより、コンパイルが正常に完了できないエラーです。

* いつ気づくか？
    * コンパイル時に、コンパイラがエラーメッセージと共に該当箇所を指摘してくれます。
* どう修正するか？
    * コンパイラのエラーメッセージをよく読み、指示された箇所の文法的な誤りを修正します。

（余談ですが……）

Javaのようなコンパイルが必要な静的型付け言語では、構文エラーがあるとプログラムを実行できません。コンパイル時に変数などの型チェック（型検査）が行われるため、実行前に多くの問題を検出できます。これは、実行時に型チェックを行う動的型付け言語（例: JavaScript, Python）との大きな違いです。
Javaはとくに、クラス定義などを通じて型を厳密に扱います。コンパイル時の型チェックは、実行時の型の不整合によるエラーを未然に防ぐ上で非常に重要です。
C言語も静的型付けですが、Javaほど厳密な型チェックを行わないため「弱い静的型付け」と言われます。一方、JavaやC#は「強い静的型付け」と呼ばれ、より多くの型に関する問題をコンパイル時に発見できます。

#### 1.1.2. 実行時エラー (Runtime Error)

プログラムの実行中に何らかの異常事態が発生し、処理の継続が困難になるエラーです。本講義の主要なテーマである「例外 (Exception)」もこの実行時エラーの一種です。

* いつ気づくか？
    * プログラム実行中に、エラーメッセージが表示されてプログラムが強制終了したり、意図しない動作をしたりした時。
* どう修正するか？
    * エラーが発生しうる箇所を特定し、後述する例外処理などを記述して、エラー発生時に適切に対応できるようにします。

#### 1.1.3. 論理エラー (Logic Error)

プログラムは正常に動作しエラーも発生しないものの、実行結果がプログラマの意図した通りにならない不具合です。

* いつ気づくか？
    * プログラムの実行結果を検証した際に、期待する結果と異なることに気づきます。
* どう修正するか？
    * デバッガを使用したり、ログを出力したりしながら、処理の流れや変数の値を確認し、不具合の原因となっているロジックの誤りを自力で特定し修正します。根気強いデバッグ作業が必要です。

論理エラーへの対処法の1つとして、入力値の検証があります。たとえば、ユーザーからの入力がシステムの定める範囲や形式に合致しているかを、処理を実行する前にチェックすることが重要です。「入力されるべき値が入っていない（nullである）」、「期待する数値範囲を超えている」といった状況は、論理エラーやそれに起因する実行時エラー（NullPointerExceptionなど）を引き起こす典型的な例です。

## 2. 実行時エラーへの対処: エラー処理と例外処理

ここからは、実行時エラー、とくに「例外的状況」にどのように対処していくかを学びます。

### 2.1. 「従来通り」の基本的なエラー処理: 早期リターン (Early Return)

メソッドの処理を進める前に、期待する前提条件が満たされているかを確認し、満たされていなければ処理を中断して早期にメソッドを終了する考え方です。これにより、不正な状態での処理継続を防ぎ、コードの可読性を高めることができます。

#### 早期リターン（ガード節）の考え方

* メソッドの冒頭で、引数の妥当性や必要なオブジェクトの状態などをチェックします。
* 不正な場合は、エラー処理（ログ出力、デフォルト値の返却、特定の例外の送出など）を行い、`return` 文でメソッドの処理を即座に終了させます。
* 正常な場合の処理は、これらのチェックの後に記述されるため、ネストが深くなるのを防ぎ、主処理のロジックが追いやすくなります。

#### 早期リターンのサンプルコード

```java
public class UserProfile {
    private String userId;
    private String name;

    public UserProfile(String userId, String name) {
        this.userId = userId;
        this.name = name;
    }

    public String getUserId() {
        return userId;
    }

    public String getName() {
        return name;
    }
}

public class UserService {

    // ユーザーIDを指定してユーザー名を取得するメソッド
    public String getUserNameById(String userId) {
        // 早期リターン: userIdがnullまたは空文字の場合は、エラーメッセージを返して処理を終了
        if (userId == null || userId.isEmpty()) {
            System.err.println("ログ: ユーザーIDが指定されていません。"); // 実際にはログ出力ライブラリを使う
            return "不明なユーザー"; // またはnullを返す、特定の例外をスローするなど、仕様による
        }

        // 早期リターン: ユーザーIDが特定の不正な形式の場合（ここでは単純な例として "admin" を不正とする）
        if ("admin".equals(userId)) {
            System.err.println("ログ: 指定されたユーザーID '" + userId + "' は不正です。");
            return "不正なユーザー";
        }

        // 本来の処理: データベースや他のサービスからユーザー情報を取得する想定
        // ここではダミーのユーザー情報を返す
        UserProfile user = findUserInDatabase(userId);

        // 早期リターン: ユーザーが見つからない場合
        if (user == null) {
            System.err.println("ログ: ユーザーID '" + userId + "' に該当するユーザーが見つかりません。");
            return "ユーザー未登録";
        }

        // 全てのチェックをパスした場合、ユーザー名を返す
        return user.getName();
    }

    // データベースからユーザー情報を取得するダミーメソッド
    private UserProfile findUserInDatabase(String userId) {
        // 本来はデータベースアクセス処理が入る
        if ("001".equals(userId)) {
            return new UserProfile("001", "山田太郎");
        }
        if ("002".equals(userId)) {
            return new UserProfile("002", "佐藤花子");
        }
        return null; // 見つからない場合はnullを返す
    }

    public static void main(String[] args) {
        UserService service = new UserService();

        System.out.println(service.getUserNameById("001"));
        System.out.println(service.getUserNameById(null));
        System.out.println(service.getUserNameById(""));
        System.out.println(service.getUserNameById("admin"));
        System.out.println(service.getUserNameById("003"));
    }
}
```

早期リターンは、ネストを浅く保ち、メソッドの前提条件を明確にする上で有効な手法です。しかし、すべての実行時エラーをこの方法だけで網羅的に対処するのは困難な場合があります。

そこでJavaには、より強力な「例外処理」の仕組みが備わっています。

### 2.2. Javaにおける例外処理 (Exception Handling)

プログラム実行中に発生する可能性のある「例外的状況」をJavaは「例外 (Exception)」オブジェクトとして表現し、これに対処するための専用の構文を提供しています。

#### 例外的状況の例

* プログラムを実行しているマシンのメモリが不足してしまった (`OutOfMemoryError`)
* ファイル処理を行いたいが、指定されたファイルが見つからない (`FileNotFoundException`)
* クラス型の変数に `null` が代入されているのに気づかずメソッドを呼び出してしまった (`NullPointerException`)
* 整数が入力されるはずの箇所に、整数以外の文字が入力されてしまった (`NumberFormatException`)
* 配列のインデックスを範囲外で指定してしまった (`ArrayIndexOutOfBoundsException`)

これらの状況が発生した際、プログラムが強制終了するのを防ぎ、適切に対応するために例外処理を行います。例外が発生することを「例外が送出される」または「例外が投げられる (throw)」と言います。

### 2.3. 例外を捕捉する: try-catch-finally構文

Javaの例外処理の基本は `try`, `catch`, `finally` の3つのキーワードを使ったブロック構造です。

#### 2.3.1. `try`ブロックと`catch`ブロック

* `try`ブロック: 例外が発生する可能性のある処理を記述します。
* `catch`ブロック: `try`ブロック内で特定の型の例外が発生した場合に、その例外を捕捉（キャッチ）し、対応する処理を記述します。

```java
public class TryCatchSample {
    public static void main(String[] args) {
        try {
            // 例外が発生する可能性のある処理
            String str = null;
            System.out.println(str.length()); // ここでNullPointerExceptionが発生する
            System.out.println("この行は実行されません。");
        } catch (NullPointerException e) {
            // NullPointerExceptionを捕捉した場合の処理
            System.err.println("ログ: NullPointerExceptionが発生しました！");
            System.err.println("ログ: エラーメッセージ: " + e.getMessage());
            // e.printStackTrace(); // 開発中はスタックトレースを出力するとデバッグに役立つ
        } catch (Exception e) {
            // NullPointerException以外の、その他のExceptionを捕捉した場合の処理
            // catchブロックは上から順に評価されるため、より具体的な例外クラスを先に書く
            System.err.println("ログ: 予期せぬ例外が発生しました: " + e.getClass().getName());
        }
        System.out.println("プログラムは処理を継続しています。");
    }
}
```

##### `catch`による例外捕捉のバリエーション

###### 複数の`catch`ブロック:
発生する例外の種類に応じて異なる処理を行いたい場合、`catch`ブロックを複数記述できます。例外の継承関係を考慮し、より具体的な例外クラス（サブクラス）の`catch`ブロックを先に、より汎用的な例外クラス（スーパークラス）の`catch`ブロックを後に記述します。

```java
import java.io.FileReader;
import java.io.FileNotFoundException;
import java.io.IOException;

public class MultipleCatchSample {
    public static void main(String[] args) {
        FileReader reader = null; // リソースはfinallyでクローズするため、tryブロックの外で宣言
        try {
            reader = new FileReader("存在しないファイル.txt"); // FileNotFoundExceptionが発生する可能性
            // reader.read(); // IOExceptionが発生する可能性 (ここではコメントアウト)
            System.out.println("ファイルオープン成功 (この行は実行されないはず)");
        } catch (FileNotFoundException e) {
            // ファイルが見つからない場合の専用処理
            System.err.println("ログ: 指定されたファイルが見つかりませんでした。");
            System.err.println("ログ: 詳細: " + e.getMessage());
        } catch (IOException e) {
            // その他の入出力関連の例外処理 (例: 読み取りエラーなど)
            System.err.println("ログ: 入出力エラーが発生しました。");
            System.err.println("ログ: 詳細: " + e.getMessage());
        } catch (Exception e) {
            // 上記以外の予期せぬ例外
            System.err.println("ログ: 予期せぬエラーが発生しました: " + e.toString());
        } finally {
            // readerがnullでなく、オープンされている場合にクローズ処理を行う
            if (reader != null) {
                try {
                    reader.close(); // close処理自体もIOExceptionを発生させる可能性がある
                    System.out.println("ファイルをクローズしました。");
                } catch (IOException e) {
                    System.err.println("ログ: ファイルのクローズに失敗しました: " + e.getMessage());
                }
            }
        }
        System.out.println("プログラム終了。");
    }
}
```

###### マルチキャッチ:
複数の異なる型の例外に対して、同じ処理を行いたい場合に、`|`（パイプ）を使って1つの`catch`ブロックでまとめて捕捉できます。

```java
public class MultiCatchSample {
    public static void main(String[] args) {
        try {
            int number = Integer.parseInt("abc"); // NumberFormatExceptionが発生
            // String str = null;
            // System.out.println(str.charAt(0)); // NullPointerExceptionが発生
        } catch (NumberFormatException | NullPointerException e) {
            // NumberFormatException または NullPointerException のどちらかが発生した場合の共通処理
            System.err.println("ログ: 数値変換エラーまたはヌルポインターエラーが発生しました。");
            System.err.println("ログ: エラーの型: " + e.getClass().getSimpleName());
            System.err.println("ログ: メッセージ: " + e.getMessage());
        }
        System.out.println("処理終了");
    }
}
```

#### 2.3.2. `finally`ブロック

`finally`ブロックは、`try`ブロック内で例外が発生したかどうか、また`catch`ブロックで例外が捕捉されたかどうかにかかわらず、必ず実行される処理を記述します。主に、ファイルハンドルやデータベース接続などのリソースを解放する処理を記述するために使用されます。

##### `try-catch-finally`構文:
例外が発生する可能性のある処理、例外発生時の処理、そして必ず実行する後処理を記述します。

```java
import java.io.FileInputStream;
import java.io.IOException;
import java.io.FileNotFoundException;

public class FinallySample {
    public static void main(String[] args) {
        FileInputStream fis = null; // リソース変数をtryブロックの外で宣言
        try {
            System.out.println("ファイルを開こうとします。");
            fis = new FileInputStream("test.txt"); // test.txt が存在しないと FileNotFoundException
            System.out.println("ファイルを開きました。データを読み込みます。");
            int data = fis.read(); // ファイルの内容を読み込む (IOExceptionの可能性)
            while(data != -1) {
                System.out.print((char)data);
                data = fis.read();
            }
            System.out.println("\nファイルの読み込みが完了しました。");

        } catch (FileNotFoundException e) {
            // ファイルが見つからなかった場合の処理
            System.err.println("ログ: ファイルが見つかりません。(" + e.getMessage() + ")");
        } catch (IOException e) {
            // その他のI/Oエラー（読み込み中など）
            System.err.println("ログ: ファイルの読み書き中に問題が発生しました。(" + e.getMessage() + ")");
        } finally {
            // finallyブロックは例外の発生有無にかかわらず実行される
            System.out.println("finallyブロックが実行されます。");
            if (fis != null) {
                try {
                    fis.close(); // ファイルストリームをクローズする
                    System.out.println("ファイルをクローズしました。");
                } catch (IOException e) {
                    // クローズ処理中の例外も考慮する
                    System.err.println("ログ: ファイルのクローズに失敗しました。(" + e.getMessage() + ")");
                }
            } else {
                System.out.println("ファイルストリームは開かれませんでした。");
            }
        }
        System.out.println("プログラムのメイン処理が終了します。");
    }
}
```

##### `try-finally`構文:
`catch`ブロックなしで、`try`ブロックの処理後（例外発生の有無にかかわらず）に必ず実行したい処理がある場合に使用します。この構文の主な目的は、リソースの解放や状態のクリーンアップなど、メソッドがどのように終了するかにかかわらず確実に行うべき後処理を記述することです。`try`ブロック内で発生した例外は捕捉されず、呼び出し元にスローされます。

###### 例外処理をしすぎないための `try-finally` の活用:
とくに、現代的なアプリケーション開発で用いられるフレームワーク（例: Spring Framework, Jakarta EEなど）の多くは、アプリケーション全体で一貫した例外処理を行うための集中的な例外ハンドリング機構（例: Spring MVCの `@ControllerAdvice` やAOPを利用した例外インターセプタなど）を備えています。

このような環境では、個々のビジネスロジックを担当するメソッド内で、発生しうるすべての例外に対して細かく `try-catch` を記述するよりも、以下のようなアプローチを推奨されることがあります。

1.  メソッド内で発生した例外（とくに、そのメソッド自身が回復処理を行えないものや、より上位のレイヤーで共通的に対処すべきもの）は、`catch` せずにそのままスローします。
2.  スローされた例外は、フレームワークが提供する共通の例外ハンドラによって捕捉され、ログ記録、エラーレスポンスの生成、トランザクションのロールバックなどの横断的な関心事が一元的に処理されます。

このアプローチにおいて、`try-finally` は非常に重要な役割を担います。たとえメソッドが例外を `catch` せずにスローする設計であっても、そのメソッド内でリソース（ファイル、ネットワーク接続、ロック、一時的なメモリ構造など）を使用した場合、それらのリソースはメソッドの処理が正常に完了しようと、例外によって中断されようと、確実に解放されなければなりません。`finally`ブロックは、このような後処理を保証します。

これにより、個々のメソッドは例外の詳細な処理方法（ユーザーへの通知方法やログのフォーマットなど）に関知せず、自身の主要な責務（ビジネスロジックの実行と、使用したリソースの適切な管理）に集中できます。結果として、コードの関心事が分離され、よりクリーンで保守しやすい構造になります。

#### 2.3.3. `try-with-resources`文

`AutoCloseable`インターフェイスまたは`Closeable`インターフェイスを実装したリソース（ファイルストリーム、DB接続など）を扱う場合、`try-with-resources`文を使用すると、`finally`ブロックで明示的に`close()`メソッドを呼び出す必要がなくなり、コードが簡潔になります。`try`ブロックを抜ける際に、自動的にリソースの`close()`メソッドが呼び出されます。

```java
import java.io.BufferedReader;
import java.io.FileReader;
import java.io.IOException;
import java.io.FileNotFoundException;

public class TryWithResourcesSample {
    public static void main(String[] args) {
        String filePath = "data.txt"; // 読み込むファイルパス

        // try-with-resources 文を使用
        // FileReaderとBufferedReaderはAutoCloseableを実装している
        try (FileReader fr = new FileReader(filePath);
             BufferedReader br = new BufferedReader(fr)) {

            // ファイルが開かれ、BufferedReaderの準備ができた
            System.out.println("ファイル '" + filePath + "' をオープンしました。内容を読み込みます:");

            String line;
            // 1行ずつ読み込み、nullになるまで (ファイルの終端まで) ループ
            while ((line = br.readLine()) != null) {
                System.out.println(line); // 読み込んだ行をコンソールに出力
            }
            // tryブロックを抜ける際に、brとfrのclose()メソッドが自動的に呼び出される
            // br.close()が先に呼ばれ、次にfr.close()が呼ばれる (宣言の逆順)

        } catch (FileNotFoundException e) {
            // ファイルが見つからなかった場合の例外処理
            System.err.println("ログ: ファイル '" + filePath + "' が見つかりません。");
            // e.printStackTrace(); // 必要に応じてスタックトレースを出力
        } catch (IOException e) {
            // その他の入出力エラー (読み込み中のエラーなど) の処理
            System.err.println("ログ: ファイルの読み込み中にI/Oエラーが発生しました。");
            System.err.println("ログ: 詳細: " + e.getMessage());
            // e.printStackTrace();
        }
        // try-with-resourcesブロックが終了した後
        System.out.println("ファイル処理が完了しました。");
    }
}
```

`try-with-resources`文は、リソース管理を簡潔かつ安全に行うための推奨される方法です。

## 3. 例外クラス

Javaでは、発生した例外の種類をクラスで分類しています。これにより、`catch`ブロックで特定の種類の例外を捕捉し、適切に対応できます。

### 3.1. 例外クラスの階層

すべての例外クラスは `java.lang.Throwable` クラスを頂点とする階層構造をなしています。`Throwable` の主要なサブクラスとして `Error` と `Exception` があります。

* `java.lang.Throwable`
    * `java.lang.Error`: システムレベルの重大なエラーで、アプリケーション側で回復することが通常困難なもの。
        * 代表例: `OutOfMemoryError`（メモリ不足）、`StackOverflowError` (スタックオーバーフロー)
        * これらの`Error`クラスの例外は、通常`catch`して回復処理を試みる対象とはなりません。
    * `java.lang.Exception`: アプリケーションレベルのエラーで、適切に対処することでプログラムの継続できる可能性があるもの。
        * `java.lang.RuntimeException`（非検査例外）: プログラマのコーディング上のミス（例: `NullPointerException`, `ArrayIndexOutOfBoundsException`）や、実行時の予期せぬ状況（例: `IllegalArgumentException`）に起因することが多い。
        * `RuntimeException`以外の`Exception`（検査例外）: 適切に処理すれば回復可能であり、コンパイラが発生をチェックする例外（例: `IOException`, `SQLException`）。

### 3.2. 検査例外 (Checked Exception) と非検査例外 (Unchecked Exception)

`Exception`クラスのサブクラスは、さらに「検査例外」と「非検査例外」に大別されます。

#### 3.2.1. 検査例外 (Checked Exception)

* `java.lang.Exception` の直接のサブクラス（ただし `java.lang.RuntimeException` とそのサブクラスを除く）。
* コンパイラが、これらの例外をスローする可能性のあるメソッドに対して、例外処理（`try-catch`ブロックで捕捉するか、`throws`宣言で呼び出し元に処理を委譲する）が記述されているかをチェックします。記述されていない場合はコンパイルエラーとなります。
* 「呼び出し側が適切に処理することで回復できる可能性がある」状況を示します。たとえば、ファイルが見つからない (`FileNotFoundException`)、ネットワーク接続に失敗した (`SocketException`) など、外部環境に依存する問題で発生しやすく、代替処理を検討すべきものです。
* 代表的な例: `IOException`, `SQLException`, `FileNotFoundException`, `ClassNotFoundException`

#### 検査例外の対処法: `try-catch` または `throws`

メソッド内で検査例外が発生する可能性のある処理を呼び出す場合、以下のいずれかの対応が必要です。

##### `try-catch`ブロックで捕捉する:

```java
import java.io.FileReader;
import java.io.FileNotFoundException;
import java.io.IOException;

public class CheckedExceptionCatchSample {
    public void readFile(String fileName) {
        FileReader reader = null;
        try {
            reader = new FileReader(fileName); // FileNotFoundException (検査例外) がスローされる可能性
            System.out.println(fileName + " を開きました。");
            // ... ファイル読み込み処理 ...
            // int charCode = reader.read(); // IOException (検査例外) がスローされる可能性
        } catch (FileNotFoundException e) {
            // このメソッド内でFileNotFoundExceptionを処理する
            System.err.println("ログ: ファイル '" + fileName + "' が見つかりません。");
        } /* catch (IOException e) {
            // その他のIOExceptionを処理する
            System.err.println("ログ: ファイル読み込み中にエラーが発生しました。");
        } */ finally {
            if (reader != null) {
                try {
                    reader.close();
                } catch (IOException e) {
                    System.err.println("ログ: ファイルクローズ時にエラーが発生しました。");
                }
            }
        }
    }

    public static void main(String[] args) {
        CheckedExceptionCatchSample sample = new CheckedExceptionCatchSample();
        sample.readFile("myDocument.txt"); // 存在しないファイル名を渡す
    }
}
```

##### `throws`宣言で呼び出し元に処理を委譲する:
メソッド自身では例外を処理せず、このメソッドの呼び出し元に例外処理の責任を移します。メソッドシグネチャに `throws 例外クラス名` を記述します。

```java
import java.io.FileReader;
import java.io.FileNotFoundException;
import java.io.IOException;

public class CheckedExceptionThrowsSample {

    // このメソッドはFileNotFoundExceptionやIOExceptionをスローする可能性があることを宣言
    public void readFileAndThrow(String fileName) throws FileNotFoundException, IOException {
        FileReader reader = null;
        try {
            reader = new FileReader(fileName);
            System.out.println(fileName + " を開きました。(readFileAndThrowメソッド内)");
            // ... ファイル読み込み処理 ...
        } finally {
            if (reader != null) {
                reader.close();
                System.out.println(fileName + " をクローズしました。(readFileAndThrowメソッド内)");
            }
        }
    }

    public static void main(String[] args) {
        CheckedExceptionThrowsSample sample = new CheckedExceptionThrowsSample();
        try {
            // readFileAndThrowメソッドを呼び出す側で例外処理を行う
            sample.readFileAndThrow("anotherDocument.txt");
        } catch (FileNotFoundException e) {
            System.err.println("mainメソッドでキャッチ: ファイル '" + e.getMessage() + "' が見つかりません。");
        } catch (IOException e) {
            System.err.println("mainメソッドでキャッチ: IOエラーが発生しました - " + e.getMessage());
        }
        System.out.println("プログラム終了");
    }
}
```

`main`メソッドで`throws`宣言を行うことも可能ですが、その場合、JVM（Java仮想マシン）が最終的な例外ハンドラとなり、例外が発生するとプログラムはスタックトレースを出力して終了します。
通常は、アプリケーションのどこかで適切に`catch`することが望ましいです。

#### 3.2.2. 非検査例外 (Unchecked Exception)

* `java.lang.RuntimeException` とそのサブクラス、および `java.lang.Error` とそのサブクラス。
* コンパイラはこれらの例外に対する処理の記述を強制しません。つまり、`try-catch` や `throws` 宣言がなくてもコンパイルエラーにはなりません。
* 主にプログラムの論理的な誤り（バグ）や、実行時の予期せぬがプログラム側の事前チェックで回避可能な状況（不正な引数など）によって発生します。
    * `NullPointerException`: `null`参照の変数に対してメンバーアクセスしようとした。
    * `ArrayIndexOutOfBoundsException`: 配列の不正なインデックスにアクセスしようとした。
    * `ArithmeticException`: ゼロによる除算など、不正な算術演算が行われた。
    * `IllegalArgumentException`: メソッドに不正な引数が渡された。
    * `NumberFormatException`: 文字列を数値に変換しようとして形式が不正だった。
* 非検査例外は、原則として`catch`して処理を継続するのではなく、コードのバグを修正することで発生自体を防ぐべきです。ただし、外部からの入力や予期せぬ状況により発生しうる一部の非検査例外（例：`NumberFormatException`）は、状況に応じて`catch`して適切に対処することもあります。

##### 非検査例外への対処

```java
public class UncheckedExceptionSample {

    public static void processArray(String[] array, int index) {
        // 事前チェックでArrayIndexOutOfBoundsExceptionを回避する例
        if (array == null || index < 0 || index >= array.length) { // nullチェックも追加
            System.err.println("ログ: 不正な配列またはインデックスです - index: " + index);
            return;
        }
        System.out.println("要素 " + index + ": " + array[index]);
    }

    public static void main(String[] args) {
        String[] data = {"apple", "banana", "cherry"};
        processArray(data, 1);
        processArray(data, 3); // 事前チェックで回避

        String text = null;
        try {
            System.out.println(text.toUpperCase()); // textがnullなのでNullPointerExceptionが発生
        } catch (NullPointerException e) {
            System.err.println("ログ: NullPointerExceptionが発生しました: " + e.getMessage());
        }

        String userInput = "123x";
        try {
            int value = Integer.parseInt(userInput); // NumberFormatException
            System.out.println("変換された数値: " + value);
        } catch (NumberFormatException e) {
            System.err.println("ログ: '" + userInput + "' は有効な数値ではありません。");
        }
    }
}
```

##### 検査例外と非検査例外の使い分けの目安

* 呼び出し側が対処することで回復の可能性がある場合（外部要因など）→ 検査例外
* プログラムのバグや、呼び出し側の事前条件違反が原因の場合 → 非検査例外

### 3.3. 独自例外クラスの作成

Java標準の例外クラスで表現しきれない、アプリケーション固有の例外的な状況を扱うために、独自の例外クラスを作成できます。

* 検査例外として扱いたい場合は `Exception` クラスまたはそのサブクラス（`RuntimeException`を除く）を継承します。
* 非検査例外として扱いたい場合は `RuntimeException` クラスまたはそのサブクラスを継承します。

```java
// アプリケーション固有の検査例外の例
class InsufficientFundsException extends Exception { // Exceptionを継承するので検査例外
    private double shortage;

    public InsufficientFundsException(String message, double shortage) {
        super(message); // 親クラス(Exception)のコンストラクタを呼び出す
        this.shortage = shortage;
    }

    public double getShortage() {
        return shortage;
    }
}

class BankAccount {
    private double balance;
    public BankAccount(double initialBalance) { this.balance = initialBalance; }

    public void withdraw(double amount) throws InsufficientFundsException {
        if (amount <= 0) {
            throw new IllegalArgumentException("引き出し額は正の数でなければなりません。");
        }
        if (amount > balance) {
            double shortBy = amount - balance;
            throw new InsufficientFundsException("残高が不足しています。", shortBy);
        }
        balance -= amount;
        System.out.println(amount + "円引き出しました。残高: " + balance + "円");
    }
    public double getBalance() { return balance; }
}

public class CustomExceptionSample {
    public static void main(String[] args) {
        BankAccount account = new BankAccount(10000.0);
        try {
            account.withdraw(5000.0);
            account.withdraw(7000.0); // InsufficientFundsException がスローされる
        } catch (InsufficientFundsException e) {
            System.err.println("エラー: " + e.getMessage() + " 不足額: " + e.getShortage() + "円");
        } catch (IllegalArgumentException e) {
            System.err.println("エラー: " + e.getMessage());
        }
    }
}
```

#### 独自例外クラスを実装するメリット

* ドメイン固有のエラー表現: アプリケーションのビジネスロジックに特化したエラー状況を、名前や付加情報によって明確に表現できます（例: `InsufficientFundsException` に不足金額 `shortage` を持たせる）。
* 特定の情報の付加: 例外発生時の詳細なコンテキスト情報（エラーコード、関連IDなど）を例外オブジェクトに含めることができます。
* 型による識別: `catch`ブロックで特定の独自例外型を捕捉することで、そのエラー専用の処理を記述しやすくなります。

#### 独自例外クラスを実装するデメリット

独自例外は強力な機能ですが、無計画な使用は以下のようなデメリットを生む可能性があります。

* クラス数の不必要な増加
    - 小さなプロジェクトや、標準例外で十分に表現できる状況で多数の独自例外クラスを作成すると、プロジェクト全体のクラス数が増加し、管理が煩雑になることがあります。結果として、コードベースの見通しが悪くなる可能性をはらんでいます。
* 過剰設計のリスク
    - 標準の `IllegalArgumentException` や `IllegalStateException` などで十分に意味が伝わるケースで、わざわざ独自の例外クラスを定義するのは過剰な設計となりがちです。標準例外のメッセージや、後述する例外の連鎖をうまく活用すれば、独自例外なしで対応できる場面も多いです。
* 学習コストの増加
    - プロジェクトに新しく参加する開発者は、標準APIの例外に加えてプロジェクト固有の例外クラス階層やそれぞれの意味、使われ方を学ぶ必要があり、学習コストが増加します。ドキュメントが整備されていない場合、このコストはさらに大きくなります。
* 標準ライブラリやフレームワークとの親和性低下
    - 広く使われているライブラリやフレームワークは、標準的な例外（`IOException`, `SQLException` など）をスローしたり、期待したりすることがあります。独自例外ばかりを使用していると、これらの外部コンポーネントとの連携がスムーズにいかない、または余計な変換処理が必要になる場合があります。
* 誤用・乱用のリスク
    - 開発者が独自例外の作成基準を誤解したり、些細な違いごとに新しい例外クラスを作成したりするなど、不適切に独自例外を乱用されるリスクがあります。これにより、例外階層が複雑怪奇になり、保守性を著しく損なうことがあります。
* メンテナンスコストの発生
    - 独自例外クラスもまたコードの一部であり、バグが含まれる可能性や、将来的な仕様変更に伴う修正が必要になる可能性があります。安易に作成された多くの独自例外は、将来的なメンテナンスの負担となります。

独自例外を作成する際は、本当にそれが必要なのか、標準APIの例外では表現できないのか、プロジェクト全体での一貫性が保たれるかなどを十分に検討することが重要です。

## 4. 例外を意図的に発生させる: `throw`

`throw`キーワードを使用すると、プログラマが明示的に例外オブジェクトを生成し、それをスロー（送出）できます。

```java
// throw 例外オブジェクト;
```

これは、特定の条件が満たされたときに、エラー状態であることを示すために使われます。組み込みの例外クラスのインスタンスを`throw`することも、自作の例外クラスのインスタンスを`throw`することも可能です。

```java
public class ThrowSample {

    public static void checkAge(int age) {
        if (age < 0) {
            // 不正な値なのでIllegalArgumentExceptionをスロー
            throw new IllegalArgumentException("年齢に負の値は指定できません: " + age);
        }
        if (age < 18) {
            // 特定の業務ルール違反 (ここではRuntimeExceptionのサブクラスとして扱う例)
            throw new RuntimeException("未成年者はアクセスできません。年齢: " + age);
        }
        System.out.println(age + "歳はアクセス許可されています。");
    }

    public static void main(String[] args) {
        try {
            checkAge(20);
            checkAge(15); // RuntimeExceptionが発生
        } catch (IllegalArgumentException e) {
            System.err.println("IllegalArgumentExceptionをキャッチ: " + e.getMessage());
        } catch (RuntimeException e) {
            System.err.println("RuntimeExceptionをキャッチ: " + e.getMessage());
        }

        try {
            checkAge(-5); // IllegalArgumentExceptionが発生
        } catch (IllegalArgumentException e) {
            System.err.println("IllegalArgumentExceptionをキャッチ: " + e.getMessage());
        }
    }
}
```

### `throws` と `throw` の違い

* `throws`（sが付く）: メソッドシグネチャの一部として使用され、そのメソッドが処理せず呼び出し元にスローする可能性のある検査例外の種類を宣言します。「このメソッドはこれらの例外を投げるかもしれないから、呼び出す側は注意してね（処理してね）」という宣言です。
* `throw`（sが付かない）: メソッド内の処理として使用され、実際に例外オブジェクトを生成してスローします。「今、ここでこの例外を発生させる！」という命令です。

## 5. 例外処理のテクニックと注意点

### 5.1. 例外処理で避けるべきこと (アンチパターン)

効果的でない、あるいは問題を引き起こしやすい例外処理のパターンが存在します。

#### 例外を無視する (Empty Catch Block):
`catch`ブロック内を空にすることは、エラーが発生した事実を隠蔽し、問題の発見を著しく遅らせるため、非常に危険です。

```java
// 避けるべき例: 例外の無視
try {
    int result = Integer.parseInt("not_a_number");
} catch (NumberFormatException e) {
    // 何もしない。これは問題の隠蔽。ログ出力すらないのは問題。
}
```

#### 例外を不適切に隠蔽する:
`catch`ブロックで汎用的すぎる例外（例: `Exception`）を捕捉し、具体的なエラー情報をログにも残さず、あたかも正常終了したかのように振る舞わせること。これも問題の特定を困難にします。

```java
// 避けるべき例: 不適切な例外の隠蔽 (不適切なエラーメッセージ)
public boolean processData(String data) {
    try {
        // dataを使った重要な処理
        if (data.equals("critical_value")) {
            throw new RuntimeException("致命的な内部エラー");
        }
        return true; // 処理成功
    } catch (Exception e) {
        // System.err.println("何らかのエラーが発生しましたが、処理は継続します。"); // 具体的なエラー情報が失われる
        // 少なくともログには詳細を記録すべき
        return false;
    }
}
```

#### 例外を通常のフロー制御に乱用する:
例外処理は、その名の通り「例外的」な状況に対処するためのものです。通常のプログラムフロー制御（たとえば、ループの終了条件など）のために例外を意図的にスローして`catch`するような使い方は、コードを読みにくくし、パフォーマンスにも悪影響を与える可能性があります。

```java
// 避けるべき例: 例外をループ制御に使う
int[] numbers = {1, 2, 3};
try {
    int i = 0;
    while (true) {
        System.out.println(numbers[i]);
        i++; // このインクリメントでいつかArrayIndexOutOfBoundsExceptionが発生する
    }
} catch (ArrayIndexOutOfBoundsException e) {
    // ループを抜けるために例外を利用している。これは不適切。
    // System.out.println("配列の最後まで表示しました。");
}
// 正しくは、forループや拡張for文、または配列の長さを条件にするべき
```

#### 過剰な防御と不必要な広範囲キャッチ:

実際には発生し得ない例外まで捕捉しようとしたり、理由なく`catch (Exception e)`ですべての例外をまとめて処理したりするのは、個別の例外に応じた適切な対応を妨げることがあります。ただし、アプリケーションの最上位レイヤーなど、予期せぬエラーをすべて捕捉してログに記録し、アプリケーション全体が停止するのを防ぐ目的で `catch (Exception e)` や `catch (Throwable t)` を使うことはあります。その場合でも、具体的なエラー情報は必ず記録すべきです。

### 5.2. より良い例外処理のために

* 具体的に対処する: 捕捉する例外は、可能な限り具体的なクラスにしましょう。`catch (Exception e)` のように汎用的な例外で捕捉する場合は、その理由（例: 未知のエラーをログに記録する最終防衛ライン）を明確にし、適切にログを記録するなどの対応をします。
* リソースは必ず解放する: ファイル、ネットワーク接続、データベース接続などのリソースは、`try-with-resources`文を使用するか、`finally`ブロックで確実に解放します。
* ログは詳細に: エラー発生時には、原因究明に必要な情報（タイムスタンプ、エラーの種類、メッセージ、スタックトレース、関連データなど）をログに記録します。
* 検査例外の適切な扱い: メソッド内で対処できない検査例外は、安易に`catch`して握りつぶすのではなく、`throws`宣言をして呼び出し元に処理を委譲することを検討します。あるいは、次節で説明する例外の連鎖を利用して、より適切な型の例外にラップしてスローすることも考慮します。

### 5.3. 例外の連鎖 (Exception Chaining)

例外の連鎖は、ある例外が別の例外を引き起こした際に、元の例外（原因例外; cause）の情報を失わずに、新しい例外でラップしてスローするテクニックです。これにより、異なる抽象度のレイヤー間でエラー情報を適切に伝達しつつ、根本原因を追跡可能にします。

#### なぜ例外の連鎖が重要か？

* 根本原因の保持: 低レベルの例外（例: `SQLException`）をそのまま上位レイヤーに伝播させると、上位レイヤーの関心事と合わない場合があります。かといって、元の例外情報を捨てて新しい例外だけをスローすると、デバッグ時に根本原因が分からなくなります。例外の連鎖は、この問題を解決します。
* 抽象化の維持: 各レイヤーは自身の抽象度に適した例外をスローしつつ、原因となった下位レイヤーの例外情報も保持できます。たとえば、データアクセス層で発生した`SQLException`を、サービス層ではよりビジネス的な`DataAccessException`（独自例外）にラップする、などです。
* デバッグの容易化: スタックトレースには、ラップされた例外と原因例外の両方が表示されるため、問題の追跡が容易になります。

#### 実装方法

`Throwable`クラスには、原因例外を保持するためのコンストラクタやメソッドが用意されています。

* コンストラクタ: `Throwable(String message, Throwable cause)`, `Throwable(Throwable cause)`
* メソッド: `initCause(Throwable cause)`（コンストラクタで原因を設定できなかった場合などに使用）

```java
// データアクセス層で発生しうる独自例外 (非検査例外の例)
class DataAccessException extends RuntimeException {
    public DataAccessException(String message, Throwable cause) {
        super(message, cause); // 原因例外(cause)をスーパークラスのコンストラクタに渡す
    }
    public DataAccessException(String message) {
        super(message);
    }
}

// サービス層
class UserRegistrationServiceWithChaining {
    // ユーザー情報をデータベースに保存するメソッド (ダミー)
    public void registerUser(String username, String password) {
        try {
            // --- データアクセス層の処理を呼び出すと想定 ---
            if (username.equals("db_error_user")) { // SQLExceptionをシミュレート
                throw new java.sql.SQLException("データベース接続エラー: タイムアウトしました。");
            }
            if (username.equals("constraint_violation_user")) { // 別のSQLExceptionをシミュレート
                throw new java.sql.SQLIntegrityConstraintViolationException("一意性制約違反: ユーザー名 " + username + " は既に使用されています。");
            }
            System.out.println("ユーザー '" + username + "' の登録処理がデータベースで成功しました。");
            // --- データアクセス層の処理ここまで ---

        } catch (java.sql.SQLIntegrityConstraintViolationException e) {
            // 具体的なSQLExceptionを捕捉し、ビジネス的な意味を持つ例外にラップして再スロー
            String errMsg = "ユーザー名 '" + username + "' は既に使用されているため登録できません。";
            throw new DataAccessException(errMsg, e); // 例外の連鎖
        } catch (java.sql.SQLException e) {
            // その他のSQLExceptionを捕捉し、汎用的なデータアクセス例外にラップ
            String errMsg = "ユーザー登録中にデータベースエラーが発生しました。詳細はシステム管理者にお問い合わせください。";
            throw new DataAccessException(errMsg, e); // 例外の連鎖
        } catch (Exception e) {
            // 予期せぬその他の例外
            String errMsg = "ユーザー登録中に予期せぬシステムエラーが発生しました。";
            throw new RuntimeException(errMsg, e); // RuntimeExceptionでラップ
        }
    }
}

public class ExceptionChainingSample {
    public static void main(String[] args) {
        UserRegistrationServiceWithChaining service = new UserRegistrationServiceWithChaining();

        // シナリオ1: 一意性制約違反
        try {
            System.out.println("シナリオ1: ユーザー名 'constraint_violation_user' で登録試行");
            service.registerUser("constraint_violation_user", "password123");
        } catch (DataAccessException e) {
            System.err.println("キャッチした例外 (DataAccessException): " + e.getMessage());
            System.err.println("原因例外 (Cause): " + e.getCause()); // getCause()で原因例外を取得できる
            // e.printStackTrace(); // スタックトレースを見ると連鎖の様子がよくわかる
        } catch (RuntimeException e) {
            System.err.println("キャッチした例外 (RuntimeException): " + e.getMessage());
            if (e.getCause() != null) System.err.println("原因例外 (Cause): " + e.getCause());
        }
        System.out.println("-----");

        // シナリオ2: その他のDBエラー
        try {
            System.out.println("シナリオ2: ユーザー名 'db_error_user' で登録試行");
            service.registerUser("db_error_user", "password456");
        } catch (DataAccessException e) {
            System.err.println("キャッチした例外 (DataAccessException): " + e.getMessage());
            System.err.println("原因例外のメッセージ: " + e.getCause().getMessage());
            // e.printStackTrace();
        }
        System.out.println("-----");
    }
}
```
`e.printStackTrace()` を実行すると、スタックトレースに `Caused by:` という形で原因となった例外の情報が表示され、問題の根本原因の特定に役立ちます。

## 6. エラー情報の提示方法: 誰に何を伝えるか

エラーや例外が発生した際に、その情報をどのように提示するかは、対象者（エンドユーザー、開発者、運用者）によって大きく異なります。

### 6.1. エンドユーザーに対するエラー表示

エンドユーザーに対してエラー情報を表示する際の基本原則は、「ユーザーを混乱させず、必要な情報だけを分かりやすく提供する」ことです。技術的な詳細をそのまま見せるのは避けるべきです。

#### 表示すべきこと（推奨）

* **明確かつ簡潔なエラー通知**:
    * 「処理中にエラーが発生しました。」
    * 「申し訳ありませんが、リクエストを完了できませんでした。」
    * 「入力内容に誤りがあります。」
* **ユーザーが次にとれるアクション (可能な場合)**:
    * 「お手数ですが、しばらく時間をおいてから再度お試しください。」
    * 「入力内容をご確認の上、もう一度実行してください。」（具体的な箇所を指摘できるならより良い）
    * 「問題が解決しない場合は、サポートまでお問い合わせください。」
* **エラー参照コード (エラーID)**:
    * 「エラーが発生しました。 (エラーコード: XXXXXXXX-XXXX-XXXX-XXXX-XXXXXXXXXXXX)」
    * このコードは、ユーザーがサポートに問い合わせる際、開発者や運用者がログから具体的なエラー状況を迅速に特定するのに役立ちます。このIDはサーバー側のログにも必ず記録します。
* **親しみやすいトーン**:
    * ユーザーを不安にさせない、丁寧で落ち着いた言葉遣いを心がけます。

#### 表示すべきでないこと（非推奨）

* **スタックトレース全体**: これは開発者向けの情報であり、エンドユーザーには意味不明で、不安を与えるだけです。また、システムの内部構造に関する情報が含まれるため、セキュリティリスクにもなり得ます。
* **生の例外メッセージ (`e.getMessage()` の直接表示)**: 例外メッセージには、時として内部的な詳細情報（ファイルパス、SQLクエリの断片など）が含まれることもあり、これらをそのまま表示するのはセキュリティ上問題があります。表示するとしても、内容を吟味し、汎用的なメッセージに置き換えるか、安全であることが確認されたメッセージのみに限定すべきです。
* **データベースのエラーコードやSQL文の断片**: これらも内部情報であり、攻撃者にヒントを与える可能性があります。
* **サーバーの内部パスや設定情報、IPアドレスなど**: これらは典型的な情報漏洩です。
* **開発者向けのデバッグ情報**:「NullPointerException at com.example.MyClass.myMethod:123」のようなメッセージはエンドユーザー向けではありません。

#### エンドユーザー向けエラー表示の例

* デスクトップアプリケーションの場合:
    * ダイアログボックスで「`エラーが発生しました。アプリケーションを再起動してください。問題が続く場合はサポートにご連絡ください。エラーコード: [エラーID]`」のように表示する。
* Webアプリケーションの場合:
    * 専用のエラーページにリダイレクトする（例: 500 Internal Server Errorページ）。
    * ページの一部に「`現在、サービスが一時的に利用できません。エラーID: [エラーID]`」のように表示する。
    * 入力フォームのエラーであれば、該当箇所の近くに「`この項目は必須です`」「`メールアドレスの形式が正しくありません`」のように具体的なエラー理由を表示する。

### 6.2. 開発者・運用者向けのログ記録

エンドユーザーには簡潔な情報のみを提示する一方、開発者や運用者は問題の原因究明と解決のために詳細な情報を必要とします。これらの情報は、サーバーサイドのログファイルや、専用のログ管理システムに記録します。

#### ログに記録すべき情報

* **タイムスタンプ**: エラー発生日時（ミリ秒単位まで）。タイムゾーン情報も重要。
* **エラーレベル**: ERROR, WARN, INFO, DEBUGなど。
* **エラーID**: エンドユーザーに提示したエラー参照コードと同じもの。
* **発生箇所**: クラス名、メソッド名、行番号など（スタックトレースから取得）。
* **スタックトレース全体**: 例外の根本原因を特定するために不可欠。例外の連鎖が使われている場合は、原因となったすべての例外のスタックトレースが含まれる。
* **例外クラス名とメッセージ**: `e.getClass().getName()` と `e.getMessage()`。
* **関連するリクエスト情報 (Webアプリケーションの場合)**:
    * リクエストURL、HTTPメソッド
    * リクエストパラメータ、ヘッダー情報（個人情報や機密情報はマスキングする）
    * ユーザーID、セッションID（特定ユーザーの行動追跡のため）
* **アプリケーションのコンテキスト情報**:
    * 処理中の主要なデータ（IDなど。機密情報はマスキング）
    * アプリケーションのバージョン
    * サーバーのホスト名、IPアドレス

Javaでは、SLF4J (Simple Logging Facade for Java) とLogbackやLog4j 2といったログライブラリを組み合わせて使用するのが一般的です。これらのライブラリは、ログのフォーマット、出力先（ファイル、コンソール、DBなど）、ローテーションなどを柔軟に設定できます。

```java
// SLF4JとLogback/Log4j2を使ったログ出力のイメージ
import org.slf4j.Logger;
import org.slf4j.LoggerFactory;
import java.util.UUID; // エラーID生成用

public class LoggingExample {
    // 各クラスでLoggerインスタンスを取得するのが一般的
    private static final Logger logger = LoggerFactory.getLogger(LoggingExample.class);

    public void processUserInput(String input) {
        String errorId = null; // エラーIDを格納する変数
        try {
            if (input == null || input.trim().isEmpty()) {
                // 業務ロジック上のエラーとして扱う（ここではIllegalArgumentException）
                throw new IllegalArgumentException("入力がnullまたは空です。");
            }
            // 何らかの処理。例えば、外部サービス呼び出しや複雑な計算など
            int value = Integer.parseInt(input); // NumberFormatExceptionが発生する可能性
            logger.info("処理成功: 入力='{}', 変換結果={}", input, value); // 通常の処理ログ (INFOレベル)

        } catch (NumberFormatException e) {
            errorId = UUID.randomUUID().toString(); // ユニークなエラーIDを生成
            // エンドユーザーには「入力形式が不正です。エラーコード: [errorId]」などと伝える
            // ログには詳細な情報を記録 (スタックトレースを含む)
            logger.error("数値変換エラーが発生しました。エラーID: {}, 入力値: '{}'", errorId, input, e);
            // ここで、ユーザーに表示するためのカスタム例外をスローすることもできる
            // throw new UserDisplayableException("入力された値「" + input + "」は有効な数値ではありません。エラーコード: " + errorId, e);

        } catch (IllegalArgumentException e) {
            errorId = UUID.randomUUID().toString();
            // エンドユーザーには「入力内容が正しくありません。エラーコード: [errorId]」など
            logger.warn("不正な引数が渡されました。エラーID: {}, 詳細: {}", errorId, e.getMessage(), e); // WARNレベルで記録

        } catch (Exception e) { // その他の予期せぬ例外
            errorId = UUID.randomUUID().toString();
            // エンドユーザーには「予期せぬエラーが発生しました。エラーコード: [errorId]」など
            logger.error("予期せぬエラーが発生しました。エラーID: {}", errorId, e);
            // throw new UserDisplayableException("システム処理中に予期せぬエラーが発生しました。エラーコード: " + errorId, e);
        } finally {
            if (errorId != null) {
                // エラーが発生した場合の共通的な後処理があればここに記述
                // (例: ユーザーにエラーIDを何らかの形で通知する最終手段など)
                System.out.println("エラーが発生しました。サポートへお問い合わせの際はエラーID「" + errorId + "」をお伝えください。");
            }
        }
    }

    public static void main(String[] args) {
        LoggingExample example = new LoggingExample();
        example.processUserInput("123");
        example.processUserInput("abc");
        example.processUserInput(null);
        example.processUserInput("   ");
    }
}
```

適切なエラー情報の提示とログ記録は、システムの信頼性、保守性、そしてユーザーの体験を向上させる上で非常に重要です。


## 7. まとめ

* エラー処理は、どんな状態であれプログラムの堅牢性を高めるために不可欠です。
* Javaの例外処理は `try-catch-finally` および `try-with-resources` が基本となります。
    - `try-finally`は、フレームワークによる集中例外処理がある場合に、リソース解放に特化して例外処理をしすぎないために有効です。
* Javaでの例外には検査例外と非検査例外があり、それぞれの性質を理解して適切に対処する必要があります。
* 独自例外の作成は慎重に行い、メリットだけでなく、クラス数の増加や学習コスト、メンテナンス性といったデメリットを十分に理解した上で判断します。
* `throw` は例外を意図的に発生させ、`throws` は例外処理を呼び出し元に委譲します。
* 例外の連鎖は、根本原因の追跡と抽象化の維持に役立ちます。
* エラー情報の提示は対象者に応じて内容を変え、エンドユーザーには技術的詳細を避け、分かりやすいメッセージとエラーIDを、ログには原因究明のための詳細情報を記録します。
* 例外処理のアンチパターンを避け、具体的で意味のある対処を心がけましょう。
